INFO 2021-04-22: Watching for file changes with StatReloader
ERROR 2021-04-22: Internal Server Error: /
Traceback (most recent call last):
  File "/usr/local/lib/python3.7/site-packages/django/core/handlers/exception.py", line 34, in inner
    response = get_response(request)
  File "/usr/local/lib/python3.7/site-packages/django/core/handlers/base.py", line 115, in _get_response
    response = self.process_exception_by_middleware(e, request)
  File "/usr/local/lib/python3.7/site-packages/django/core/handlers/base.py", line 113, in _get_response
    response = wrapped_callback(request, *callback_args, **callback_kwargs)
  File "/Users/kdang/Desktop/collectuserinfo/collect_app/views.py", line 31, in getnameage
    add_entry(user_dict)
  File "/Users/kdang/Desktop/collectuserinfo/tallytable.py", line 27, in add_entry
    ini_tally[user_dict['os']] += 1
KeyError: 'Mac OS X'
WARNING 2021-04-22: Not Found: /favicon.ico
INFO 2021-04-22: /Users/kdang/Desktop/collectuserinfo/collect_app/views.py changed, reloading.
INFO 2021-04-22: Watching for file changes with StatReloader
INFO 2021-04-22: /Users/kdang/Desktop/collectuserinfo/collect_app/views.py changed, reloading.
INFO 2021-04-22: Watching for file changes with StatReloader
INFO 2021-04-22: Watching for file changes with StatReloader
ERROR 2021-04-22: Internal Server Error: /
Traceback (most recent call last):
  File "/usr/local/lib/python3.7/site-packages/django/core/handlers/exception.py", line 34, in inner
    response = get_response(request)
  File "/usr/local/lib/python3.7/site-packages/django/core/handlers/base.py", line 115, in _get_response
    response = self.process_exception_by_middleware(e, request)
  File "/usr/local/lib/python3.7/site-packages/django/core/handlers/base.py", line 113, in _get_response
    response = wrapped_callback(request, *callback_args, **callback_kwargs)
  File "/Users/kdang/Desktop/collectuserinfo/collect_app/views.py", line 31, in getnameage
    add_entry(user_dict)
  File "/Users/kdang/Desktop/collectuserinfo/tallytable.py", line 27, in add_entry
    ini_tally[user_dict['os']] += 1
KeyError: 'Mac OS X'
INFO 2021-04-22: /Users/kdang/Desktop/collectuserinfo/collect_app/views.py changed, reloading.
INFO 2021-04-22: Watching for file changes with StatReloader
ERROR 2021-04-22: Internal Server Error: /
Traceback (most recent call last):
  File "/usr/local/lib/python3.7/site-packages/django/core/handlers/exception.py", line 34, in inner
    response = get_response(request)
  File "/usr/local/lib/python3.7/site-packages/django/core/handlers/base.py", line 115, in _get_response
    response = self.process_exception_by_middleware(e, request)
  File "/usr/local/lib/python3.7/site-packages/django/core/handlers/base.py", line 113, in _get_response
    response = wrapped_callback(request, *callback_args, **callback_kwargs)
  File "/Users/kdang/Desktop/collectuserinfo/collect_app/views.py", line 31, in getnameage
    add_entry(user_dict)
  File "/Users/kdang/Desktop/collectuserinfo/tallytable.py", line 44, in add_entry
    ReturnValues = 'UPDATED_NEW'
  File "/usr/local/lib/python3.7/site-packages/boto3/resources/factory.py", line 520, in do_action
    response = action(self, *args, **kwargs)
  File "/usr/local/lib/python3.7/site-packages/boto3/resources/action.py", line 83, in __call__
    response = getattr(parent.meta.client, operation_name)(**params)
  File "/usr/local/lib/python3.7/site-packages/botocore/client.py", line 357, in _api_call
    return self._make_api_call(operation_name, kwargs)
  File "/usr/local/lib/python3.7/site-packages/botocore/client.py", line 661, in _make_api_call
    raise error_class(parsed_response, operation_name)
botocore.exceptions.ClientError: An error occurred (ValidationException) when calling the UpdateItem operation: Invalid UpdateExpression: Syntax error; token: "OS", near: "Mac OS ="
INFO 2021-04-22: /Users/kdang/Desktop/collectuserinfo/collect_app/views.py changed, reloading.
INFO 2021-04-22: Watching for file changes with StatReloader
ERROR 2021-04-22: Internal Server Error: /
Traceback (most recent call last):
  File "/usr/local/lib/python3.7/site-packages/django/core/handlers/exception.py", line 34, in inner
    response = get_response(request)
  File "/usr/local/lib/python3.7/site-packages/django/core/handlers/base.py", line 115, in _get_response
    response = self.process_exception_by_middleware(e, request)
  File "/usr/local/lib/python3.7/site-packages/django/core/handlers/base.py", line 113, in _get_response
    response = wrapped_callback(request, *callback_args, **callback_kwargs)
  File "/Users/kdang/Desktop/collectuserinfo/collect_app/views.py", line 31, in getnameage
    add_entry(user_dict)
  File "/Users/kdang/Desktop/collectuserinfo/tallytable.py", line 44, in add_entry
    ReturnValues = 'UPDATED_NEW'
  File "/usr/local/lib/python3.7/site-packages/boto3/resources/factory.py", line 520, in do_action
    response = action(self, *args, **kwargs)
  File "/usr/local/lib/python3.7/site-packages/boto3/resources/action.py", line 83, in __call__
    response = getattr(parent.meta.client, operation_name)(**params)
  File "/usr/local/lib/python3.7/site-packages/botocore/client.py", line 357, in _api_call
    return self._make_api_call(operation_name, kwargs)
  File "/usr/local/lib/python3.7/site-packages/botocore/client.py", line 661, in _make_api_call
    raise error_class(parsed_response, operation_name)
botocore.exceptions.ClientError: An error occurred (ValidationException) when calling the UpdateItem operation: Invalid UpdateExpression: Syntax error; token: "OS", near: "Mac OS ="
INFO 2021-04-22: /Users/kdang/Desktop/collectuserinfo/collect_app/views.py changed, reloading.
INFO 2021-04-22: Watching for file changes with StatReloader
ERROR 2021-04-22: Internal Server Error: /
Traceback (most recent call last):
  File "/usr/local/lib/python3.7/site-packages/django/core/handlers/exception.py", line 34, in inner
    response = get_response(request)
  File "/usr/local/lib/python3.7/site-packages/django/core/handlers/base.py", line 115, in _get_response
    response = self.process_exception_by_middleware(e, request)
  File "/usr/local/lib/python3.7/site-packages/django/core/handlers/base.py", line 113, in _get_response
    response = wrapped_callback(request, *callback_args, **callback_kwargs)
  File "/Users/kdang/Desktop/collectuserinfo/collect_app/views.py", line 31, in getnameage
    add_entry(user_dict)
  File "/Users/kdang/Desktop/collectuserinfo/tallytable.py", line 44, in add_entry
    ReturnValues = 'UPDATED_NEW'
  File "/usr/local/lib/python3.7/site-packages/boto3/resources/factory.py", line 520, in do_action
    response = action(self, *args, **kwargs)
  File "/usr/local/lib/python3.7/site-packages/boto3/resources/action.py", line 83, in __call__
    response = getattr(parent.meta.client, operation_name)(**params)
  File "/usr/local/lib/python3.7/site-packages/botocore/client.py", line 357, in _api_call
    return self._make_api_call(operation_name, kwargs)
  File "/usr/local/lib/python3.7/site-packages/botocore/client.py", line 661, in _make_api_call
    raise error_class(parsed_response, operation_name)
botocore.exceptions.ClientError: An error occurred (ValidationException) when calling the UpdateItem operation: Invalid UpdateExpression: Syntax error; token: "OS", near: "Mac OS ="
INFO 2021-04-22: /Users/kdang/Desktop/collectuserinfo/collect_app/views.py changed, reloading.
INFO 2021-04-22: Watching for file changes with StatReloader
ERROR 2021-04-22: Internal Server Error: /
Traceback (most recent call last):
  File "/usr/local/lib/python3.7/site-packages/django/core/handlers/exception.py", line 34, in inner
    response = get_response(request)
  File "/usr/local/lib/python3.7/site-packages/django/core/handlers/base.py", line 115, in _get_response
    response = self.process_exception_by_middleware(e, request)
  File "/usr/local/lib/python3.7/site-packages/django/core/handlers/base.py", line 113, in _get_response
    response = wrapped_callback(request, *callback_args, **callback_kwargs)
  File "/Users/kdang/Desktop/collectuserinfo/collect_app/views.py", line 31, in getnameage
    add_entry(user_dict)
  File "/Users/kdang/Desktop/collectuserinfo/tallytable.py", line 44, in add_entry
    ReturnValues = 'UPDATED_NEW'
  File "/usr/local/lib/python3.7/site-packages/boto3/resources/factory.py", line 520, in do_action
    response = action(self, *args, **kwargs)
  File "/usr/local/lib/python3.7/site-packages/boto3/resources/action.py", line 83, in __call__
    response = getattr(parent.meta.client, operation_name)(**params)
  File "/usr/local/lib/python3.7/site-packages/botocore/client.py", line 357, in _api_call
    return self._make_api_call(operation_name, kwargs)
  File "/usr/local/lib/python3.7/site-packages/botocore/client.py", line 661, in _make_api_call
    raise error_class(parsed_response, operation_name)
botocore.exceptions.ClientError: An error occurred (ValidationException) when calling the UpdateItem operation: Invalid UpdateExpression: Syntax error; token: "OS", near: "Mac OS ="
INFO 2021-04-22: /Users/kdang/Desktop/collectuserinfo/collect_app/views.py changed, reloading.
INFO 2021-04-22: Watching for file changes with StatReloader
INFO 2021-04-22: Watching for file changes with StatReloader
ERROR 2021-04-22: Internal Server Error: /
Traceback (most recent call last):
  File "/usr/local/lib/python3.7/site-packages/django/core/handlers/exception.py", line 34, in inner
    response = get_response(request)
  File "/usr/local/lib/python3.7/site-packages/django/core/handlers/base.py", line 115, in _get_response
    response = self.process_exception_by_middleware(e, request)
  File "/usr/local/lib/python3.7/site-packages/django/core/handlers/base.py", line 113, in _get_response
    response = wrapped_callback(request, *callback_args, **callback_kwargs)
  File "/Users/kdang/Desktop/collectuserinfo/collect_app/views.py", line 31, in getnameage
    add_entry(user_dict)
  File "/Users/kdang/Desktop/collectuserinfo/tallytable.py", line 44, in add_entry
    ReturnValues = 'UPDATED_NEW'
  File "/usr/local/lib/python3.7/site-packages/boto3/resources/factory.py", line 520, in do_action
    response = action(self, *args, **kwargs)
  File "/usr/local/lib/python3.7/site-packages/boto3/resources/action.py", line 83, in __call__
    response = getattr(parent.meta.client, operation_name)(**params)
  File "/usr/local/lib/python3.7/site-packages/botocore/client.py", line 357, in _api_call
    return self._make_api_call(operation_name, kwargs)
  File "/usr/local/lib/python3.7/site-packages/botocore/client.py", line 661, in _make_api_call
    raise error_class(parsed_response, operation_name)
botocore.exceptions.ClientError: An error occurred (ValidationException) when calling the UpdateItem operation: Invalid UpdateExpression: Syntax error; token: "OS", near: "Mac OS ="
INFO 2021-04-22: /Users/kdang/Desktop/collectuserinfo/tallytable.py changed, reloading.
INFO 2021-04-22: Watching for file changes with StatReloader
ERROR 2021-04-22: Internal Server Error: /
Traceback (most recent call last):
  File "/usr/local/lib/python3.7/site-packages/django/core/handlers/exception.py", line 34, in inner
    response = get_response(request)
  File "/usr/local/lib/python3.7/site-packages/django/core/handlers/base.py", line 115, in _get_response
    response = self.process_exception_by_middleware(e, request)
  File "/usr/local/lib/python3.7/site-packages/django/core/handlers/base.py", line 113, in _get_response
    response = wrapped_callback(request, *callback_args, **callback_kwargs)
  File "/Users/kdang/Desktop/collectuserinfo/collect_app/views.py", line 31, in getnameage
    add_entry(user_dict)
  File "/Users/kdang/Desktop/collectuserinfo/tallytable.py", line 42, in add_entry
    ':t': ini_tally['Totalusers']
  File "/usr/local/lib/python3.7/site-packages/boto3/resources/factory.py", line 520, in do_action
    response = action(self, *args, **kwargs)
  File "/usr/local/lib/python3.7/site-packages/boto3/resources/action.py", line 83, in __call__
    response = getattr(parent.meta.client, operation_name)(**params)
  File "/usr/local/lib/python3.7/site-packages/botocore/client.py", line 357, in _api_call
    return self._make_api_call(operation_name, kwargs)
  File "/usr/local/lib/python3.7/site-packages/botocore/client.py", line 661, in _make_api_call
    raise error_class(parsed_response, operation_name)
botocore.exceptions.ClientError: An error occurred (ValidationException) when calling the UpdateItem operation: Invalid UpdateExpression: Syntax error; token: "OS", near: "Mac OS ="
INFO 2021-04-22: /Users/kdang/Desktop/collectuserinfo/tallytable.py changed, reloading.
INFO 2021-04-22: Watching for file changes with StatReloader
ERROR 2021-04-22: Internal Server Error: /
Traceback (most recent call last):
  File "/usr/local/lib/python3.7/site-packages/django/core/handlers/exception.py", line 34, in inner
    response = get_response(request)
  File "/usr/local/lib/python3.7/site-packages/django/core/handlers/base.py", line 115, in _get_response
    response = self.process_exception_by_middleware(e, request)
  File "/usr/local/lib/python3.7/site-packages/django/core/handlers/base.py", line 113, in _get_response
    response = wrapped_callback(request, *callback_args, **callback_kwargs)
  File "/Users/kdang/Desktop/collectuserinfo/collect_app/views.py", line 31, in getnameage
    add_entry(user_dict)
  File "/Users/kdang/Desktop/collectuserinfo/tallytable.py", line 43, in add_entry
    ':t': ini_tally['Totalusers']
  File "/usr/local/lib/python3.7/site-packages/boto3/resources/factory.py", line 520, in do_action
    response = action(self, *args, **kwargs)
  File "/usr/local/lib/python3.7/site-packages/boto3/resources/action.py", line 83, in __call__
    response = getattr(parent.meta.client, operation_name)(**params)
  File "/usr/local/lib/python3.7/site-packages/botocore/client.py", line 357, in _api_call
    return self._make_api_call(operation_name, kwargs)
  File "/usr/local/lib/python3.7/site-packages/botocore/client.py", line 661, in _make_api_call
    raise error_class(parsed_response, operation_name)
botocore.exceptions.ClientError: An error occurred (ValidationException) when calling the UpdateItem operation: Invalid UpdateExpression: Syntax error; token: "OS", near: "Mac OS ="
INFO 2021-04-22: /Users/kdang/Desktop/collectuserinfo/collect_app/views.py changed, reloading.
INFO 2021-04-22: Watching for file changes with StatReloader
INFO 2021-04-22: /Users/kdang/Desktop/collectuserinfo/tallytable.py changed, reloading.
INFO 2021-04-22: Watching for file changes with StatReloader
ERROR 2021-04-22: Internal Server Error: /
Traceback (most recent call last):
  File "/usr/local/lib/python3.7/site-packages/django/core/handlers/exception.py", line 34, in inner
    response = get_response(request)
  File "/usr/local/lib/python3.7/site-packages/django/core/handlers/base.py", line 115, in _get_response
    response = self.process_exception_by_middleware(e, request)
  File "/usr/local/lib/python3.7/site-packages/django/core/handlers/base.py", line 113, in _get_response
    response = wrapped_callback(request, *callback_args, **callback_kwargs)
  File "/Users/kdang/Desktop/collectuserinfo/collect_app/views.py", line 30, in getnameage
    add_entry(user_dict)
  File "/Users/kdang/Desktop/collectuserinfo/tallytable.py", line 44, in add_entry
    ':t': ini_tally['Totalusers']
  File "/usr/local/lib/python3.7/site-packages/boto3/resources/factory.py", line 520, in do_action
    response = action(self, *args, **kwargs)
  File "/usr/local/lib/python3.7/site-packages/boto3/resources/action.py", line 83, in __call__
    response = getattr(parent.meta.client, operation_name)(**params)
  File "/usr/local/lib/python3.7/site-packages/botocore/client.py", line 357, in _api_call
    return self._make_api_call(operation_name, kwargs)
  File "/usr/local/lib/python3.7/site-packages/botocore/client.py", line 661, in _make_api_call
    raise error_class(parsed_response, operation_name)
botocore.exceptions.ClientError: An error occurred (ValidationException) when calling the UpdateItem operation: Invalid UpdateExpression: Syntax error; token: "OS", near: "Mac OS ="
INFO 2021-04-22: /Users/kdang/Desktop/collectuserinfo/tallytable.py changed, reloading.
INFO 2021-04-22: Watching for file changes with StatReloader
INFO 2021-04-22: /Users/kdang/Desktop/collectuserinfo/tallytable.py changed, reloading.
INFO 2021-04-22: Watching for file changes with StatReloader
ERROR 2021-04-22: Internal Server Error: /
Traceback (most recent call last):
  File "/usr/local/lib/python3.7/site-packages/django/core/handlers/exception.py", line 34, in inner
    response = get_response(request)
  File "/usr/local/lib/python3.7/site-packages/django/core/handlers/base.py", line 115, in _get_response
    response = self.process_exception_by_middleware(e, request)
  File "/usr/local/lib/python3.7/site-packages/django/core/handlers/base.py", line 113, in _get_response
    response = wrapped_callback(request, *callback_args, **callback_kwargs)
  File "/Users/kdang/Desktop/collectuserinfo/collect_app/views.py", line 30, in getnameage
    add_entry(user_dict)
  File "/Users/kdang/Desktop/collectuserinfo/tallytable.py", line 45, in add_entry
    ':t': ini_tally['Totalusers']
  File "/usr/local/lib/python3.7/site-packages/boto3/resources/factory.py", line 520, in do_action
    response = action(self, *args, **kwargs)
  File "/usr/local/lib/python3.7/site-packages/boto3/resources/action.py", line 83, in __call__
    response = getattr(parent.meta.client, operation_name)(**params)
  File "/usr/local/lib/python3.7/site-packages/botocore/client.py", line 357, in _api_call
    return self._make_api_call(operation_name, kwargs)
  File "/usr/local/lib/python3.7/site-packages/botocore/client.py", line 661, in _make_api_call
    raise error_class(parsed_response, operation_name)
botocore.exceptions.ClientError: An error occurred (ValidationException) when calling the UpdateItem operation: Invalid UpdateExpression: Syntax error; token: "OS", near: "Mac OS ="
INFO 2021-04-22: /Users/kdang/Desktop/collectuserinfo/tallytable.py changed, reloading.
INFO 2021-04-22: Watching for file changes with StatReloader
ERROR 2021-04-22: Internal Server Error: /
Traceback (most recent call last):
  File "/usr/local/lib/python3.7/site-packages/django/core/handlers/exception.py", line 34, in inner
    response = get_response(request)
  File "/usr/local/lib/python3.7/site-packages/django/core/handlers/base.py", line 115, in _get_response
    response = self.process_exception_by_middleware(e, request)
  File "/usr/local/lib/python3.7/site-packages/django/core/handlers/base.py", line 113, in _get_response
    response = wrapped_callback(request, *callback_args, **callback_kwargs)
  File "/Users/kdang/Desktop/collectuserinfo/collect_app/views.py", line 30, in getnameage
    add_entry(user_dict)
  File "/Users/kdang/Desktop/collectuserinfo/tallytable.py", line 47, in add_entry
    ReturnValues = 'UPDATED_NEW'
  File "/usr/local/lib/python3.7/site-packages/boto3/resources/factory.py", line 520, in do_action
    response = action(self, *args, **kwargs)
  File "/usr/local/lib/python3.7/site-packages/boto3/resources/action.py", line 83, in __call__
    response = getattr(parent.meta.client, operation_name)(**params)
  File "/usr/local/lib/python3.7/site-packages/botocore/client.py", line 357, in _api_call
    return self._make_api_call(operation_name, kwargs)
  File "/usr/local/lib/python3.7/site-packages/botocore/client.py", line 661, in _make_api_call
    raise error_class(parsed_response, operation_name)
botocore.exceptions.ClientError: An error occurred (ValidationException) when calling the UpdateItem operation: Invalid UpdateExpression: Syntax error; token: "OS", near: "Mac OS ="
INFO 2021-04-22: /Users/kdang/Desktop/collectuserinfo/collect_app/views.py changed, reloading.
INFO 2021-04-22: Watching for file changes with StatReloader
INFO 2021-04-22: /Users/kdang/Desktop/collectuserinfo/collect_app/views.py changed, reloading.
INFO 2021-04-22: Watching for file changes with StatReloader
INFO 2021-04-22: {"source_IP": "127.0.0.1", "browser": "Chrome", "os": "Mac"}
INFO 2021-04-22: /Users/kdang/Desktop/collectuserinfo/tallytable.py changed, reloading.
INFO 2021-04-22: Watching for file changes with StatReloader
INFO 2021-04-22: {"source_IP": "127.0.0.1", "browser": "Chrome", "os": "Mac"}
INFO 2021-04-22: /Users/kdang/Desktop/collectuserinfo/tallytable.py changed, reloading.
INFO 2021-04-22: Watching for file changes with StatReloader
INFO 2021-04-22: {"source_IP": "127.0.0.1", "browser": "Chrome", "os": "Mac"}
INFO 2021-04-22: Watching for file changes with StatReloader
INFO 2021-04-22: Watching for file changes with StatReloader
INFO 2021-04-22: {"source_IP": "127.0.0.1", "browser": "Chrome", "os": "Mac"}
INFO 2021-04-22: {"source_IP": "127.0.0.1", "browser": "Chrome", "os": "Mac"}
INFO 2021-04-22: {"source_IP": "127.0.0.1", "browser": "Chrome", "os": "Mac"}
INFO 2021-04-23: Watching for file changes with StatReloader
INFO 2021-04-23: {"source_IP": "127.0.0.1", "browser": "Chrome", "os": "Mac"}
INFO 2021-04-23: /Users/kdang/Desktop/collectuserinfo/tallytable.py changed, reloading.
INFO 2021-04-23: Watching for file changes with StatReloader
INFO 2021-04-23: /Users/kdang/Desktop/collectuserinfo/tallytable.py changed, reloading.
INFO 2021-04-23: Watching for file changes with StatReloader
INFO 2021-04-23: /Users/kdang/Desktop/collectuserinfo/tallytable.py changed, reloading.
INFO 2021-04-23: Watching for file changes with StatReloader
INFO 2021-04-23: /Users/kdang/Desktop/collectuserinfo/tallytable.py changed, reloading.
INFO 2021-04-23: Watching for file changes with StatReloader
INFO 2021-04-23: /Users/kdang/Desktop/collectuserinfo/tallytable.py changed, reloading.
INFO 2021-04-23: Watching for file changes with StatReloader
INFO 2021-04-23: {"source_IP": "127.0.0.1", "browser": "Chrome", "os": "Mac"}
INFO 2021-04-23: /Users/kdang/Desktop/collectuserinfo/collect_app/views.py changed, reloading.
INFO 2021-04-23: Watching for file changes with StatReloader
INFO 2021-04-23: /Users/kdang/Desktop/collectuserinfo/collect_app/views.py changed, reloading.
INFO 2021-04-23: Watching for file changes with StatReloader
INFO 2021-04-23: {"source_IP": "127.0.0.1", "browser": "Chrome", "os": "Mac"}
INFO 2021-04-23: /Users/kdang/Desktop/collectuserinfo/tallytable.py changed, reloading.
INFO 2021-04-23: Watching for file changes with StatReloader
INFO 2021-04-23: /Users/kdang/Desktop/collectuserinfo/collect_app/views.py changed, reloading.
INFO 2021-04-23: Watching for file changes with StatReloader
INFO 2021-04-23: Watching for file changes with StatReloader
INFO 2021-04-23: /Users/kdang/Desktop/collectuserinfo/collect_app/views.py changed, reloading.
INFO 2021-04-23: Watching for file changes with StatReloader
INFO 2021-04-23: /Users/kdang/Desktop/collectuserinfo/graph.py changed, reloading.
INFO 2021-04-23: Watching for file changes with StatReloader
INFO 2021-04-23: /Users/kdang/Desktop/collectuserinfo/graph.py changed, reloading.
INFO 2021-04-23: Watching for file changes with StatReloader
ERROR 2021-04-23: Internal Server Error: /
Traceback (most recent call last):
  File "/usr/local/lib/python3.7/site-packages/django/core/handlers/exception.py", line 34, in inner
    response = get_response(request)
  File "/usr/local/lib/python3.7/site-packages/django/core/handlers/base.py", line 115, in _get_response
    response = self.process_exception_by_middleware(e, request)
  File "/usr/local/lib/python3.7/site-packages/django/core/handlers/base.py", line 113, in _get_response
    response = wrapped_callback(request, *callback_args, **callback_kwargs)
  File "/Users/kdang/Desktop/collectuserinfo/collect_app/views.py", line 33, in getnameage
    chart = pie(tally)
  File "/Users/kdang/Desktop/collectuserinfo/graph.py", line 7, in pie
    os_sizes = [tally['Windows', tally['Mac']]]
KeyError: ('Windows', Decimal('44'))
INFO 2021-04-23: /Users/kdang/Desktop/collectuserinfo/graph.py changed, reloading.
INFO 2021-04-23: Watching for file changes with StatReloader
ERROR 2021-04-23: Internal Server Error: /
Traceback (most recent call last):
  File "/usr/local/lib/python3.7/site-packages/django/core/handlers/exception.py", line 34, in inner
    response = get_response(request)
  File "/usr/local/lib/python3.7/site-packages/django/core/handlers/base.py", line 115, in _get_response
    response = self.process_exception_by_middleware(e, request)
  File "/usr/local/lib/python3.7/site-packages/django/core/handlers/base.py", line 113, in _get_response
    response = wrapped_callback(request, *callback_args, **callback_kwargs)
  File "/Users/kdang/Desktop/collectuserinfo/collect_app/views.py", line 33, in getnameage
    chart = pie(tally)
  File "/Users/kdang/Desktop/collectuserinfo/graph.py", line 10, in pie
    ax1.pie(sizes, labels=labels, shadow=True)
NameError: name 'sizes' is not defined
INFO 2021-04-23: /Users/kdang/Desktop/collectuserinfo/graph.py changed, reloading.
INFO 2021-04-23: Watching for file changes with StatReloader
ERROR 2021-04-23: Internal Server Error: /
Traceback (most recent call last):
  File "/usr/local/lib/python3.7/site-packages/django/core/handlers/exception.py", line 34, in inner
    response = get_response(request)
  File "/usr/local/lib/python3.7/site-packages/django/core/handlers/base.py", line 115, in _get_response
    response = self.process_exception_by_middleware(e, request)
  File "/usr/local/lib/python3.7/site-packages/django/core/handlers/base.py", line 113, in _get_response
    response = wrapped_callback(request, *callback_args, **callback_kwargs)
  File "/Users/kdang/Desktop/collectuserinfo/collect_app/views.py", line 33, in getnameage
    chart = pie(tally)
  File "/Users/kdang/Desktop/collectuserinfo/graph.py", line 10, in pie
    ax1.pie(os_izes, labels=os_labels, shadow=True)
NameError: name 'os_izes' is not defined
INFO 2021-04-23: /Users/kdang/Desktop/collectuserinfo/graph.py changed, reloading.
INFO 2021-04-23: Watching for file changes with StatReloader
INFO 2021-04-23: Watching for file changes with StatReloader
INFO 2021-04-23: {"source_IP": "127.0.0.1", "browser": "Chrome", "os": "Mac"}
INFO 2021-04-23: /Users/kdang/Desktop/collectuserinfo/graph.py changed, reloading.
INFO 2021-04-23: Watching for file changes with StatReloader
INFO 2021-04-23: /Users/kdang/Desktop/collectuserinfo/graph.py changed, reloading.
INFO 2021-04-23: Watching for file changes with StatReloader
INFO 2021-04-23: Watching for file changes with StatReloader
INFO 2021-04-23: {"source_IP": "127.0.0.1", "browser": "Chrome", "os": "Mac"}
INFO 2021-04-23: {"source_IP": "127.0.0.1", "browser": "Chrome", "os": "Mac"}
INFO 2021-04-23: /Users/kdang/Desktop/collectuserinfo/graph.py changed, reloading.
INFO 2021-04-23: Watching for file changes with StatReloader
INFO 2021-04-23: {"source_IP": "127.0.0.1", "browser": "Chrome", "os": "Mac"}
INFO 2021-04-23: {"source_IP": "127.0.0.1", "browser": "Chrome", "os": "Mac"}
INFO 2021-04-23: {"source_IP": "127.0.0.1", "browser": "Chrome", "os": "Mac"}
INFO 2021-04-23: {"source_IP": "127.0.0.1", "browser": "Chrome", "os": "Mac"}
INFO 2021-04-23: /Users/kdang/Desktop/collectuserinfo/graph.py changed, reloading.
INFO 2021-04-23: Watching for file changes with StatReloader
INFO 2021-04-23: {"source_IP": "127.0.0.1", "browser": "Chrome", "os": "Mac"}
INFO 2021-04-23: /Users/kdang/Desktop/collectuserinfo/graph.py changed, reloading.
INFO 2021-04-23: Watching for file changes with StatReloader
INFO 2021-04-23: /Users/kdang/Desktop/collectuserinfo/collect_app/views.py changed, reloading.
INFO 2021-04-23: Watching for file changes with StatReloader
ERROR 2021-04-23: Internal Server Error: /
Traceback (most recent call last):
  File "/usr/local/lib/python3.7/site-packages/django/core/handlers/exception.py", line 34, in inner
    response = get_response(request)
  File "/usr/local/lib/python3.7/site-packages/django/core/handlers/base.py", line 115, in _get_response
    response = self.process_exception_by_middleware(e, request)
  File "/usr/local/lib/python3.7/site-packages/django/core/handlers/base.py", line 113, in _get_response
    response = wrapped_callback(request, *callback_args, **callback_kwargs)
  File "/Users/kdang/Desktop/collectuserinfo/collect_app/views.py", line 34, in getnameage
    chart = base64.b64encode(png)
  File "/usr/local/anaconda3/lib/python3.7/base64.py", line 58, in b64encode
    encoded = binascii.b2a_base64(s, newline=False)
TypeError: a bytes-like object is required, not 'Figure'
INFO 2021-04-23: /Users/kdang/Desktop/collectuserinfo/collect_app/views.py changed, reloading.
INFO 2021-04-23: Watching for file changes with StatReloader
ERROR 2021-04-23: Internal Server Error: /
Traceback (most recent call last):
  File "/usr/local/lib/python3.7/site-packages/django/core/handlers/exception.py", line 34, in inner
    response = get_response(request)
  File "/usr/local/lib/python3.7/site-packages/django/core/handlers/base.py", line 115, in _get_response
    response = self.process_exception_by_middleware(e, request)
  File "/usr/local/lib/python3.7/site-packages/django/core/handlers/base.py", line 113, in _get_response
    response = wrapped_callback(request, *callback_args, **callback_kwargs)
  File "/Users/kdang/Desktop/collectuserinfo/collect_app/views.py", line 34, in getnameage
    chart = base64.b64encode(png)
  File "/usr/local/anaconda3/lib/python3.7/base64.py", line 58, in b64encode
    encoded = binascii.b2a_base64(s, newline=False)
TypeError: a bytes-like object is required, not 'Figure'
INFO 2021-04-23: /Users/kdang/Desktop/collectuserinfo/collect_app/views.py changed, reloading.
INFO 2021-04-23: Watching for file changes with StatReloader
ERROR 2021-04-23: Internal Server Error: /
Traceback (most recent call last):
  File "/usr/local/lib/python3.7/site-packages/django/core/handlers/exception.py", line 34, in inner
    response = get_response(request)
  File "/usr/local/lib/python3.7/site-packages/django/core/handlers/base.py", line 115, in _get_response
    response = self.process_exception_by_middleware(e, request)
  File "/usr/local/lib/python3.7/site-packages/django/core/handlers/base.py", line 113, in _get_response
    response = wrapped_callback(request, *callback_args, **callback_kwargs)
  File "/Users/kdang/Desktop/collectuserinfo/collect_app/views.py", line 34, in getnameage
    chart = base64.b64encode(image)
  File "/usr/local/anaconda3/lib/python3.7/base64.py", line 58, in b64encode
    encoded = binascii.b2a_base64(s, newline=False)
TypeError: a bytes-like object is required, not 'Figure'
INFO 2021-04-23: /Users/kdang/Desktop/collectuserinfo/graph.py changed, reloading.
INFO 2021-04-23: Watching for file changes with StatReloader
ERROR 2021-04-23: Internal Server Error: /
Traceback (most recent call last):
  File "/usr/local/lib/python3.7/site-packages/django/core/handlers/exception.py", line 34, in inner
    response = get_response(request)
  File "/usr/local/lib/python3.7/site-packages/django/core/handlers/base.py", line 115, in _get_response
    response = self.process_exception_by_middleware(e, request)
  File "/usr/local/lib/python3.7/site-packages/django/core/handlers/base.py", line 113, in _get_response
    response = wrapped_callback(request, *callback_args, **callback_kwargs)
  File "/Users/kdang/Desktop/collectuserinfo/collect_app/views.py", line 33, in getnameage
    image = pie(tally)
  File "/Users/kdang/Desktop/collectuserinfo/graph.py", line 18, in pie
    buffer.seek(0)
NameError: name 'buffer' is not defined
INFO 2021-04-23: /Users/kdang/Desktop/collectuserinfo/graph.py changed, reloading.
INFO 2021-04-23: Watching for file changes with StatReloader
ERROR 2021-04-23: Internal Server Error: /
Traceback (most recent call last):
  File "/usr/local/lib/python3.7/site-packages/django/core/handlers/exception.py", line 34, in inner
    response = get_response(request)
  File "/usr/local/lib/python3.7/site-packages/django/core/handlers/base.py", line 115, in _get_response
    response = self.process_exception_by_middleware(e, request)
  File "/usr/local/lib/python3.7/site-packages/django/core/handlers/base.py", line 113, in _get_response
    response = wrapped_callback(request, *callback_args, **callback_kwargs)
  File "/Users/kdang/Desktop/collectuserinfo/collect_app/views.py", line 33, in getnameage
    image = pie(tally)
  File "/Users/kdang/Desktop/collectuserinfo/graph.py", line 19, in pie
    buffer.seek(0)
NameError: name 'buffer' is not defined
INFO 2021-04-23: /Users/kdang/Desktop/collectuserinfo/graph.py changed, reloading.
INFO 2021-04-23: Watching for file changes with StatReloader
INFO 2021-04-23: /Users/kdang/Desktop/collectuserinfo/graph.py changed, reloading.
INFO 2021-04-23: Watching for file changes with StatReloader
INFO 2021-04-23: {"source_IP": "127.0.0.1", "browser": "Chrome", "os": "Mac"}
INFO 2021-04-23: {"source_IP": "127.0.0.1", "browser": "Chrome", "os": "Mac"}
INFO 2021-04-23: /Users/kdang/Desktop/collectuserinfo/graph.py changed, reloading.
INFO 2021-04-23: Watching for file changes with StatReloader
INFO 2021-04-23: /Users/kdang/Desktop/collectuserinfo/graph.py changed, reloading.
INFO 2021-04-23: Watching for file changes with StatReloader
INFO 2021-04-23: {"source_IP": "127.0.0.1", "browser": "Chrome", "os": "Mac"}
INFO 2021-04-26: Watching for file changes with StatReloader
INFO 2021-04-26: Watching for file changes with StatReloader
INFO 2021-04-26: {"source_IP": "127.0.0.1", "browser": "Chrome", "os": "Mac"}
WARNING 2021-04-26: Not Found: /favicon.ico
INFO 2021-04-26: /Users/kdang/Desktop/collectuserinfo/graph.py changed, reloading.
INFO 2021-04-26: Watching for file changes with StatReloader
INFO 2021-04-26: /Users/kdang/Desktop/collectuserinfo/graph.py changed, reloading.
INFO 2021-04-26: Watching for file changes with StatReloader
INFO 2021-04-26: Watching for file changes with StatReloader
INFO 2021-04-26: Watching for file changes with StatReloader
INFO 2021-04-26: Watching for file changes with StatReloader
ERROR 2021-04-26: Internal Server Error: /
Traceback (most recent call last):
  File "/usr/local/lib/python3.7/site-packages/django/core/handlers/exception.py", line 34, in inner
    response = get_response(request)
  File "/usr/local/lib/python3.7/site-packages/django/core/handlers/base.py", line 115, in _get_response
    response = self.process_exception_by_middleware(e, request)
  File "/usr/local/lib/python3.7/site-packages/django/core/handlers/base.py", line 113, in _get_response
    response = wrapped_callback(request, *callback_args, **callback_kwargs)
  File "/Users/kdang/Desktop/collectuserinfo/collect_app/views.py", line 33, in getnameage
    image = graph.pie_os(tally)
  File "/Users/kdang/Desktop/collectuserinfo/graph.py", line 15, in pie_os
    plt.pie(os_sizes, explode=explode, labels=os_labels, autopct='%1.1f %%', shadow=True, startangle=90)
NameError: name 'explode' is not defined
INFO 2021-04-26: /Users/kdang/Desktop/collectuserinfo/graph.py changed, reloading.
INFO 2021-04-26: Watching for file changes with StatReloader
INFO 2021-04-26: {"source_IP": "127.0.0.1", "browser": "Chrome", "os": "Mac"}
INFO 2021-04-26: /Users/kdang/Desktop/collectuserinfo/graph.py changed, reloading.
INFO 2021-04-26: Watching for file changes with StatReloader
ERROR 2021-04-26: Internal Server Error: /
Traceback (most recent call last):
  File "/usr/local/lib/python3.7/site-packages/django/core/handlers/exception.py", line 34, in inner
    response = get_response(request)
  File "/usr/local/lib/python3.7/site-packages/django/core/handlers/base.py", line 115, in _get_response
    response = self.process_exception_by_middleware(e, request)
  File "/usr/local/lib/python3.7/site-packages/django/core/handlers/base.py", line 113, in _get_response
    response = wrapped_callback(request, *callback_args, **callback_kwargs)
  File "/Users/kdang/Desktop/collectuserinfo/collect_app/views.py", line 33, in getnameage
    image = graph.pie_os(tally)
  File "/Users/kdang/Desktop/collectuserinfo/graph.py", line 15, in pie_os
    plt.pie(os_sizes, labels=os_labels, autopct='%1.1f %%', shadow=True, startangle=90)
  File "/usr/local/lib/python3.7/site-packages/matplotlib/pyplot.py", line 2781, in pie
    data is not None else {}))
  File "/usr/local/lib/python3.7/site-packages/matplotlib/__init__.py", line 1589, in inner
    return func(ax, *map(sanitize_sequence, args), **kwargs)
  File "/usr/local/lib/python3.7/site-packages/matplotlib/axes/_axes.py", line 2966, in pie
    x = np.asarray(x, np.float32)
  File "/usr/local/lib/python3.7/site-packages/numpy/core/numeric.py", line 538, in asarray
    return array(a, dtype, copy=False, order=order)
ValueError: could not convert string to float: 'Other_OS'
INFO 2021-04-26: /Users/kdang/Desktop/collectuserinfo/graph.py changed, reloading.
INFO 2021-04-26: Watching for file changes with StatReloader
INFO 2021-04-26: {"source_IP": "127.0.0.1", "browser": "Chrome", "os": "Mac"}
INFO 2021-04-26: /Users/kdang/Desktop/collectuserinfo/graph.py changed, reloading.
INFO 2021-04-26: Watching for file changes with StatReloader
INFO 2021-04-26: {"source_IP": "127.0.0.1", "browser": "Chrome", "os": "Mac"}
INFO 2021-04-26: /Users/kdang/Desktop/collectuserinfo/graph.py changed, reloading.
INFO 2021-04-26: Watching for file changes with StatReloader
INFO 2021-04-26: /Users/kdang/Desktop/collectuserinfo/graph.py changed, reloading.
INFO 2021-04-26: Watching for file changes with StatReloader
INFO 2021-04-26: /Users/kdang/Desktop/collectuserinfo/collect_app/views.py changed, reloading.
INFO 2021-04-26: Watching for file changes with StatReloader
ERROR 2021-04-26: Internal Server Error: /
Traceback (most recent call last):
  File "/usr/local/lib/python3.7/site-packages/django/core/handlers/exception.py", line 34, in inner
    response = get_response(request)
  File "/usr/local/lib/python3.7/site-packages/django/core/handlers/base.py", line 115, in _get_response
    response = self.process_exception_by_middleware(e, request)
  File "/usr/local/lib/python3.7/site-packages/django/core/handlers/base.py", line 113, in _get_response
    response = wrapped_callback(request, *callback_args, **callback_kwargs)
  File "/Users/kdang/Desktop/collectuserinfo/collect_app/views.py", line 35, in getnameage
    chart_os = chart.decode('utf-8')
NameError: name 'chart' is not defined
INFO 2021-04-26: /Users/kdang/Desktop/collectuserinfo/collect_app/views.py changed, reloading.
INFO 2021-04-26: Watching for file changes with StatReloader
INFO 2021-04-26: /Users/kdang/Desktop/collectuserinfo/collect_app/views.py changed, reloading.
INFO 2021-04-26: Watching for file changes with StatReloader
INFO 2021-04-26: {"source_IP": "127.0.0.1", "browser": "Chrome", "os": "Mac"}
ERROR 2021-04-26: Internal Server Error: /
Traceback (most recent call last):
  File "/usr/local/lib/python3.7/site-packages/django/core/handlers/exception.py", line 34, in inner
    response = get_response(request)
  File "/usr/local/lib/python3.7/site-packages/django/core/handlers/base.py", line 115, in _get_response
    response = self.process_exception_by_middleware(e, request)
  File "/usr/local/lib/python3.7/site-packages/django/core/handlers/base.py", line 113, in _get_response
    response = wrapped_callback(request, *callback_args, **callback_kwargs)
  File "/Users/kdang/Desktop/collectuserinfo/collect_app/views.py", line 50, in getnameage
    "chart_os": char_os,
NameError: name 'char_os' is not defined
INFO 2021-04-26: {"source_IP": "127.0.0.1", "browser": "Chrome", "os": "Mac"}
ERROR 2021-04-26: Internal Server Error: /
Traceback (most recent call last):
  File "/usr/local/lib/python3.7/site-packages/django/core/handlers/exception.py", line 34, in inner
    response = get_response(request)
  File "/usr/local/lib/python3.7/site-packages/django/core/handlers/base.py", line 115, in _get_response
    response = self.process_exception_by_middleware(e, request)
  File "/usr/local/lib/python3.7/site-packages/django/core/handlers/base.py", line 113, in _get_response
    response = wrapped_callback(request, *callback_args, **callback_kwargs)
  File "/Users/kdang/Desktop/collectuserinfo/collect_app/views.py", line 50, in getnameage
    "chart_os": char_os,
NameError: name 'char_os' is not defined
INFO 2021-04-26: {"source_IP": "127.0.0.1", "browser": "Chrome", "os": "Mac"}
ERROR 2021-04-26: Internal Server Error: /
Traceback (most recent call last):
  File "/usr/local/lib/python3.7/site-packages/django/core/handlers/exception.py", line 34, in inner
    response = get_response(request)
  File "/usr/local/lib/python3.7/site-packages/django/core/handlers/base.py", line 115, in _get_response
    response = self.process_exception_by_middleware(e, request)
  File "/usr/local/lib/python3.7/site-packages/django/core/handlers/base.py", line 113, in _get_response
    response = wrapped_callback(request, *callback_args, **callback_kwargs)
  File "/Users/kdang/Desktop/collectuserinfo/collect_app/views.py", line 50, in getnameage
    "chart_os": char_os,
NameError: name 'char_os' is not defined
INFO 2021-04-26: /Users/kdang/Desktop/collectuserinfo/collect_app/views.py changed, reloading.
INFO 2021-04-26: Watching for file changes with StatReloader
INFO 2021-04-26: {"source_IP": "127.0.0.1", "browser": "Chrome", "os": "Mac"}
INFO 2021-04-26: /Users/kdang/Desktop/collectuserinfo/collect_app/views.py changed, reloading.
INFO 2021-04-26: Watching for file changes with StatReloader
INFO 2021-04-26: /Users/kdang/Desktop/collectuserinfo/collect_app/views.py changed, reloading.
INFO 2021-04-26: Watching for file changes with StatReloader
INFO 2021-04-26: /Users/kdang/Desktop/collectuserinfo/collect_app/views.py changed, reloading.
INFO 2021-04-26: Watching for file changes with StatReloader
INFO 2021-04-26: {"source_IP": "127.0.0.1", "browser": "Chrome", "os": "Mac"}
INFO 2021-04-26: {"source_IP": "127.0.0.1", "browser": "Chrome", "os": "Mac"}
INFO 2021-04-26: {"source_IP": "127.0.0.1", "browser": "Chrome", "os": "Mac"}
INFO 2021-04-26: {"source_IP": "127.0.0.1", "browser": "Chrome", "os": "Mac"}
INFO 2021-04-26: {"source_IP": "127.0.0.1", "browser": "Chrome", "os": "Mac"}
INFO 2021-04-26: {"source_IP": "127.0.0.1", "browser": "Chrome", "os": "Mac"}
INFO 2021-04-26: {"source_IP": "127.0.0.1", "browser": "Chrome", "os": "Mac"}
INFO 2021-04-26: /Users/kdang/Desktop/collectuserinfo/graph.py changed, reloading.
INFO 2021-04-26: Watching for file changes with StatReloader
INFO 2021-04-26: {"source_IP": "127.0.0.1", "browser": "Chrome", "os": "Mac"}
INFO 2021-04-26: /Users/kdang/Desktop/collectuserinfo/tallytable.py changed, reloading.
INFO 2021-04-26: Watching for file changes with StatReloader
INFO 2021-04-26: /Users/kdang/Desktop/collectuserinfo/graph.py changed, reloading.
INFO 2021-04-26: Watching for file changes with StatReloader
INFO 2021-04-26: /Users/kdang/Desktop/collectuserinfo/graph.py changed, reloading.
INFO 2021-04-26: Watching for file changes with StatReloader
INFO 2021-04-26: /Users/kdang/Desktop/collectuserinfo/graph.py changed, reloading.
INFO 2021-04-26: Watching for file changes with StatReloader
ERROR 2021-04-26: Internal Server Error: /
Traceback (most recent call last):
  File "/usr/local/lib/python3.7/site-packages/django/core/handlers/exception.py", line 34, in inner
    response = get_response(request)
  File "/usr/local/lib/python3.7/site-packages/django/core/handlers/base.py", line 115, in _get_response
    response = self.process_exception_by_middleware(e, request)
  File "/usr/local/lib/python3.7/site-packages/django/core/handlers/base.py", line 113, in _get_response
    response = wrapped_callback(request, *callback_args, **callback_kwargs)
  File "/Users/kdang/Desktop/collectuserinfo/collect_app/views.py", line 34, in getnameage
    image_os = graph.pie_os(tally)
  File "/Users/kdang/Desktop/collectuserinfo/graph.py", line 18, in pie_os
    plt.pie(os_sizes, labels=os_labels, color=colors, autopct='%1.1f%%', shadow=True, startangle=90)
TypeError: pie() got an unexpected keyword argument 'color'
INFO 2021-04-26: /Users/kdang/Desktop/collectuserinfo/graph.py changed, reloading.
INFO 2021-04-26: Watching for file changes with StatReloader
ERROR 2021-04-26: Internal Server Error: /
Traceback (most recent call last):
  File "/usr/local/lib/python3.7/site-packages/django/core/handlers/exception.py", line 34, in inner
    response = get_response(request)
  File "/usr/local/lib/python3.7/site-packages/django/core/handlers/base.py", line 115, in _get_response
    response = self.process_exception_by_middleware(e, request)
  File "/usr/local/lib/python3.7/site-packages/django/core/handlers/base.py", line 113, in _get_response
    response = wrapped_callback(request, *callback_args, **callback_kwargs)
  File "/Users/kdang/Desktop/collectuserinfo/collect_app/views.py", line 34, in getnameage
    image_os = graph.pie_os(tally)
  File "/Users/kdang/Desktop/collectuserinfo/graph.py", line 18, in pie_os
    plt.pie(os_sizes, labels=os_labels, colors=colors, autopct='%1.1f%%', shadow=True, startangle=90)
  File "/usr/local/lib/python3.7/site-packages/matplotlib/pyplot.py", line 2781, in pie
    data is not None else {}))
  File "/usr/local/lib/python3.7/site-packages/matplotlib/__init__.py", line 1589, in inner
    return func(ax, *map(sanitize_sequence, args), **kwargs)
  File "/usr/local/lib/python3.7/site-packages/matplotlib/axes/_axes.py", line 3027, in pie
    **wedgeprops)
  File "/usr/local/lib/python3.7/site-packages/matplotlib/patches.py", line 1076, in __init__
    Patch.__init__(self, **kwargs)
  File "/usr/local/lib/python3.7/site-packages/matplotlib/patches.py", line 82, in __init__
    self.set_facecolor(facecolor)
  File "/usr/local/lib/python3.7/site-packages/matplotlib/patches.py", line 319, in set_facecolor
    self._set_facecolor(color)
  File "/usr/local/lib/python3.7/site-packages/matplotlib/patches.py", line 307, in _set_facecolor
    self._facecolor = colors.to_rgba(color, alpha)
  File "/usr/local/lib/python3.7/site-packages/matplotlib/colors.py", line 177, in to_rgba
    rgba = _to_rgba_no_colorcycle(c, alpha)
  File "/usr/local/lib/python3.7/site-packages/matplotlib/colors.py", line 231, in _to_rgba_no_colorcycle
    raise ValueError("Invalid RGBA argument: {!r}".format(orig_c))
ValueError: Invalid RGBA argument: 'mageta'
INFO 2021-04-26: /Users/kdang/Desktop/collectuserinfo/graph.py changed, reloading.
INFO 2021-04-26: Watching for file changes with StatReloader
INFO 2021-04-26: {"source_IP": "127.0.0.1", "browser": "Chrome", "os": "Mac"}
INFO 2021-04-26: /Users/kdang/Desktop/collectuserinfo/graph.py changed, reloading.
INFO 2021-04-26: Watching for file changes with StatReloader
INFO 2021-04-26: {"source_IP": "127.0.0.1", "browser": "Chrome", "os": "Mac"}
